Workbook

Sheet Project Summary
B1: Address Redacted · RENOVATION PROJECT BUDGET
B2: Pasadena, TX | Active Renovation | Budget as of 2025
B4: DEAL SUMMARY
B5: Metric | C5: Value | E5: Metric | F5: Value
B6: Purchase Price | C6: 75200 | E6: ARV (Low Estimate) | F6: 215000
B7: Net Acquisition Cost | C7: =F22 -> 81125 | E7: ARV (High Estimate) | F7: 230000
B8: Pre-Reno Appraised Value | C8: 160000 | E8: Projected Profit (Low) | F8: =F6-C10 -> 71852.337
B9: Total Renovation Budget | C9: =F29+F39 -> 62022.663 | E9: Projected Profit (High) | F9: =F7-C10 -> 86852.337
B10: TOTAL ALL-IN COST | C10: =C7+C9 -> 143147.66 | E10: Return on Cost (Low) | F10: =(F6-C10)/C10 -> 0.50194558
B11: Instant Equity (Pre-Reno) | C11: =C8-C10 -> 16852.337 | E11: Return on Cost (High) | F11: =(F7-C10)/C10 -> 0.60673248
B13: Color Key: Blue text = Hardcoded input | Black = Formula | Green = Cross-sheet link | PERT = (Opt + 4×ML + Pess) ÷ 6 hrs × $25/hr
B15: HOUSE ACQUISITION
B16: Description | C16: Amount | D16: — | E16: — | F16: Total | G16: Notes / Assumptions | H16: Reference
B17: Property Purchase Price | C17: 75200 | D17: — | E17: — | F17: =C17 -> 75200 | G17: Agreed sale price | H17: Purchase Agreement
B18: Loan / Mortgage Amount | C18: 71440 | D18: — | E18: — | F18: =C18 -> 71440 | G18: Financed portion (informational) | H18: Lender / Loan Docs
B19: Down Payment (Cash Equity) | C19: 9685 | D19: — | E19: — | F19: =C19 -> 9685 | G19: Purchase price minus loan | H19: Calculated
B20: Total w/ All Closing Fees | C20: 83375 | D20: — | E20: — | F20: =C20 -> 83375 | G20: Includes title, escrow & all fees | H20: Settlement Statement
B21: Seller Contribution | C21: 2250 | D21: — | E21: — | F21: =C21 -> 2250 | G21: Seller-paid closing cost credit | H21: Settlement Statement
B22: NET ACQUISITION COST | D22: — | E22: — | F22: =C20-C21 -> 81125 | G22: Total closing cost minus seller contribution | H22: Calculated
B24: CONTRACTOR BIDS (Material & Labor Included in Bid Price)
B25: Description | C25: Material Cost | D25: Labor Hours | E25: Labor Cost | F25: Total Cost | G25: Notes / Assumptions | H25: Source / Detail
B26: Foundation + Flatwork (Driveway & Sidewalk) | C26: Bundled | D26: Bundled | E26: 10627 | F26: =E26 -> 10627 | G26: Incl. $2,000 discount; Driveway, Sidewalk, Interior metal beam under BR2 | H26: Contractor Bid
B27: New Roof (incl. Tear-Off) | C27: Bundled | D27: Bundled | E27: 8267.25 | F27: =E27 -> 8267.25 | G27: Incl. $1,200 discount; full tear-off & replace | H27: Contractor Bid
B28: Electrical Panel Upgrade (100A → 200A) | C28: Bundled | D28: Bundled | E28: 4300 | F28: =E28 -> 4300 | G28: Service upgrade; incl. panel + breakers + permit + labor | H28: Contractor Bid
B29: CONTRACTOR SUBTOTAL | F29: =SUM(F26:F28) -> 23194.25
B31: SELF-MANAGED WORK (Material + Labor @ $25/hr)
B32: Category | C32: Material Cost | D32: Labor Hours | E32: Labor Cost | F32: Total Cost | G32: Includes | H32: Source
B33: Exterior Envelope | C33: ='Line Item Details'!F9+'Line Item Details'!F16+'Line Item Details'!F24+'Line Item Details'!F29+'Line Item Details'!F39+'Line Item Details'!F50+'Line Item Details'!F75+'Line Item Details'!F184+'Line Item Details'!F189 -> 5654.6 | D33: ='PERT Labor Estimates'!G7+'PERT Labor Estimates'!G8+'PERT Labor Estimates'!G9+'PERT Labor Estimates'!G11+'PERT Labor Estimates'!G12+'PERT Labor Estimates'!G13+'PERT Labor Estimates'!G15+'PERT Labor Estimates'!G16+'PERT Labor Estimates'!G17 -> 229.33333 | E33: ='PERT Labor Estimates'!H7+'PERT Labor Estimates'!H8+'PERT Labor Estimates'!H9+'PERT Labor Estimates'!H11+'PERT Labor Estimates'!H12+'PERT Labor Estimates'!H13+'PERT Labor Estimates'!H15+'PERT Labor Estimates'!H16+'PERT Labor Estimates'!H17 -> 5733.3333 | F33: =C33+E33 -> 11387.933 | G33: Siding, sheathing, eave, insulation, windows/door, wall framing, gutters, covered deck, shed removal | H33: PERT + LID sheets
B34: Exterior Finishes | C34: ='Line Item Details'!F58+'Line Item Details'!F68 -> 1624.4 | D34: ='PERT Labor Estimates'!G10+'PERT Labor Estimates'!G14 -> 67.333333 | E34: ='PERT Labor Estimates'!H10+'PERT Labor Estimates'!H14 -> 1683.3333 | F34: =C34+E34 -> 3307.7333 | G34: Exterior paint, fence (full perimeter) | H34: PERT + LID sheets
B35: Interior Systems | C35: ='Line Item Details'!F92+'Line Item Details'!F99+'Line Item Details'!F105 -> 7313.9 | D35: ='PERT Labor Estimates'!G19+'PERT Labor Estimates'!G20+'PERT Labor Estimates'!G21 -> 127.83333 | E35: ='PERT Labor Estimates'!H19+'PERT Labor Estimates'!H20+'PERT Labor Estimates'!H21 -> 3195.8333 | F35: =C35+E35 -> 10509.733 | G35: HVAC, electrical rough-in, water heater | H35: PERT + LID sheets
B36: Interior Finishes | C36: ='Line Item Details'!F115+'Line Item Details'!F125+'Line Item Details'!F142+'Line Item Details'!F159+'Line Item Details'!F168+'Line Item Details'!F176 -> 4064.68 | D36: ='PERT Labor Estimates'!G22+'PERT Labor Estimates'!G23+'PERT Labor Estimates'!G24+'PERT Labor Estimates'!G25+'PERT Labor Estimates'!G26+'PERT Labor Estimates'!G27 -> 142.33333 | E36: ='PERT Labor Estimates'!H22+'PERT Labor Estimates'!H23+'PERT Labor Estimates'!H24+'PERT Labor Estimates'!H25+'PERT Labor Estimates'!H26+'PERT Labor Estimates'!H27 -> 3558.3333 | F36: =C36+E36 -> 7623.0133 | G36: Doors, interior paint, laundry, garage drywall, 1/2 bath, full bath | H36: PERT + LID sheets
B37: Outdoor Structures | C37: 0 | D37: 0 | E37: 0 | F37: 0 | G37: Included in Exterior Envelope | H37: PERT + LID sheets
B38: Misc / Contingency | C38: 6000 | D38: 0 | E38: =D38*25 -> 0 | F38: =C38+E38 -> 6000 | G38: Buffer for extras not captured elsewhere | H38: Hardcoded estimate
B39: SELF-MANAGED SUBTOTAL | C39: =SUM(C33:C38) -> 24657.58 | D39: =SUM(D33:D38) -> 566.83333 | E39: =SUM(E33:E38) -> 14170.833 | F39: =SUM(F33:F38) -> 38828.413
C41: Total Labor Hrs | D41: Total Labor Cost | E41: Total Project Cost
B42: ★ TOTAL PROJECT COST | C42: =D39 -> 566.83333 | D42: =E39 -> 14170.833 | E42: =F22+F29+F39 -> 143147.66

Sheet PERT Labor Estimates
B1: PERT LABOR COST ESTIMATES
B3: LABOR RATE ($/hr): | E3: 25
B5: Trade / Item | C5: Fixed Hrs (override) | D5: Opt (hrs) | E5: Most Likely (hrs) | F5: Pess (hrs) | G5: PERT Hours | H5: Labor Cost (@ $25/hr) | I5: Assumptions / Notes
B6: — EXTERIOR WORK —
B7: Siding / Trim | C7: — | D7: 20 | E7: 27 | F7: 35 | G7: =(D7+4*E7+F7)/6 -> 27.166667 | H7: =G7*$E$3 -> 679.16667 | I7: Fixed 55 hrs — siding panels, trim install (140-hr pkg)
B8: Sheathing + WP | C8: — | D8: 20 | E8: 30 | F8: 40 | G8: =(D8+4*E8+F8)/6 -> 30 | H8: =G8*$E$3 -> 750 | I8: Fixed 18 hrs — sheathing + waterproof membrane (140-hr pkg)
B9: Eave | C9: — | D9: 20 | E9: 25 | F9: 30 | G9: =(D9+4*E9+F9)/6 -> 25 | H9: =G9*$E$3 -> 625 | I9: Fixed 25 hrs — carpenter, fascia & soffit
B10: Exterior Paint | C10: — | D10: 20 | E10: 36 | F10: 64 | G10: =(D10+4*E10+F10)/6 -> 38 | H10: =G10*$E$3 -> 950 | I10: Painter crew; pressure wash, prime, 2-coat spray
B11: Insulation | C11: — | D11: 15 | E11: 20 | F11: 30 | G11: =(D11+4*E11+F11)/6 -> 20.833333 | H11: =G11*$E$3 -> 520.83333 | I11: Fixed 20 hrs — batt/blow-in whole house (140-hr pkg)
B12: Windows / Patio Door | C12: — | D12: 50 | E12: 60 | F12: 75 | G12: =(D12+4*E12+F12)/6 -> 60.833333 | H12: =G12*$E$3 -> 1520.8333 | I12: Fixed 22 hrs — remove, install, seal, trim (140-hr pkg)
B13: Fix Damaged Studs | C13: — | D13: 5 | E13: 25 | F13: 50 | G13: =(D13+4*E13+F13)/6 -> 25.833333 | H13: =G13*$E$3 -> 645.83333 | I13: Fixed 25 hrs — stud repair, sistering, blocking (140-hr pkg)
B14: New Fence | C14: — | D14: 16 | E14: 28 | F14: 48 | G14: =(D14+4*E14+F14)/6 -> 29.333333 | H14: =G14*$E$3 -> 733.33333 | I14: Fence crew; panels, rails, gates, hardware
B15: Gutters | C15: — | D15: 6 | E15: 10 | F15: 16 | G15: =(D15+4*E15+F15)/6 -> 10.333333 | H15: =G15*$E$3 -> 258.33333 | I15: Gutter crew; hang sections, install outlets, downspouts, grade & test
B16: Covered Deck | C16: — | D16: 12 | E16: 20 | F16: 36 | G16: =(D16+4*E16+F16)/6 -> 21.333333 | H16: =G16*$E$3 -> 533.33333 | I16: Carpenter; framing, decking, metal roof
B17: Shed Remove | C17: — | D17: 4 | E17: 8 | F17: 12 | G17: =(D17+4*E17+F17)/6 -> 8 | H17: =G17*$E$3 -> 200 | I17: Demo, load, haul — confirm dumpster
B18: — INTERIOR & RENOVATION —
B19: Water Heater | C19: — | D19: 3 | E19: 6 | F19: 12 | G19: =(D19+4*E19+F19)/6 -> 6.5 | H19: =G19*$E$3 -> 162.5 | I19: Plumber: connections, drain pan, flush & test
B20: Electrical (Rough-In) | C20: — | D20: 40 | E20: 80 | F20: 120 | G20: =(D20+4*E20+F20)/6 -> 80 | H20: =G20*$E$3 -> 2000 | I20: Licensed electrician; rough-in wiring & devices
B21: HVAC | C21: — | D21: 24 | E21: 40 | F21: 64 | G21: =(D21+4*E21+F21)/6 -> 41.333333 | H21: =G21*$E$3 -> 1033.3333 | I21: HVAC tech; refrigerant, ductwork, startup
B22: Doors | C22: — | D22: 6 | E22: 12 | F22: 20 | G22: =(D22+4*E22+F22)/6 -> 12.333333 | H22: =G22*$E$3 -> 308.33333 | I22: Carpenter; hang, shim, hardware — all 6 doors
B23: Interior Paint | C23: — | D23: 30 | E23: 52 | F23: 88 | G23: =(D23+4*E23+F23)/6 -> 54.333333 | H23: =G23*$E$3 -> 1358.3333 | I23: Painter; walls/ceiling, trim, doors
B24: Laundry Rebuild | C24: — | D24: 16 | E24: 28 | F24: 48 | G24: =(D24+4*E24+F24)/6 -> 29.333333 | H24: =G24*$E$3 -> 733.33333 | I24: Framer + plumber; wall framing + plumbing rough-in
B25: Garage Drywall | C25: — | D25: 6 | E25: 10 | F25: 16 | G25: =(D25+4*E25+F25)/6 -> 10.333333 | H25: =G25*$E$3 -> 258.33333 | I25: Drywall finisher; hang, tape, mud, sand, prime
B26: 1/2 Bath | C26: — | D26: 7 | E26: 13 | F26: 21 | G26: =(D26+4*E26+F26)/6 -> 13.333333 | H26: =G26*$E$3 -> 333.33333 | I26: Tile setter + plumber/electrician; tile, toilet, faucet, mirror, exhaust fan
B27: Full Bath | C27: — | D27: 12 | E27: 22 | F27: 36 | G27: =(D27+4*E27+F27)/6 -> 22.666667 | H27: =G27*$E$3 -> 566.66667 | I27: Tile setter + plumber + carpenter; tile, shower, vanity, faucet, sink rough-in, exhaust fan
B28: TOTAL ESTIMATED LABOR | G28: =SUMPRODUCT((ISNUMBER(G7:G27))*G7:G27) -> 566.83333 | H28: =SUMPRODUCT((ISNUMBER(H7:H27))*H7:H27) -> 14170.833

Sheet Line Item Details
B1: 1204 DUNSTAN RD · LINE ITEM COST BREAKDOWNS
B2: Material costs by work category | Blue = input | Black = formula | Update quantities to match actual purchases
B4: SIDING (64 linear ft)
B5: Component / Description | C5: Quantity | D5: Unit | E5: Unit Cost | F5: Line Total | G5: Notes
B6: Siding Panels | C6: 16 | D6: ea | E6: 40 | F6: =C6*E6 -> 640 | G6: LP Smartside 4×8 cedar stamped panel
B7: Nails | C7: 1 | D7: box | E7: 48 | F7: =C7*E7 -> 48 | G7: 2-3/8 in. x 0.113 in. 21° Plastic Collated Exterior Galvanized Ring Shank Round Head Framing Nails 1000 per Box
B8: Siding Battens | C8: 28 | D8: ea | E8: 24 | F8: =C8*E8 -> 672 | G8: 16'×4"×4/4 LP Smartside cedar stamped
B9: Subtotal | F9: =SUM(F6:F8) -> 1360
B11: SHEATHING + WATERPROOFING
B12: Component / Description | C12: Quantity | D12: Unit | E12: Unit Cost | F12: Line Total | G12: Notes
B13: ForceField Plywood Sheathing | C13: 15 | D13: ea | E13: 27 | F13: =C13*E13 -> 405 | G13: Weather-resistant sheathing; existing partially retained
B14: Nails | C14: 1 | D14: box | E14: 48 | F14: =C14*E14 -> 48 | G14: 2-3/8 in. x 0.113 in. 21° Plastic Collated Exterior Galvanized Ring Shank Round Head Framing Nails 1000 per Box
B15: ForceField Sheathing Seam Tape | C15: 3 | D15: roll | E15: 20 | F15: =C15*E15 -> 60 | G15: Seam sealing at panel joints
B16: Subtotal | F16: =SUM(F13:F15) -> 513
B18: EAVE (fascia & soffit)
B19: Component / Description | C19: Quantity | D19: Unit | E19: Unit Cost | F19: Line Total | G19: Notes
B20: Plywood for Soffit | C20: 1 | D20: ea | E20: 35 | F20: =C20*E20 -> 35 | G20: This is for fixing a few sections of soffit - 3/8 sanded pine plywood
B21: Fascia - Corner | C21: 1 | D21: ea | E21: 22 | F21: =C21*E21 -> 22 | G21: This is for fixing a few rotted sections of soffit - 1"x12"x6' common pine
B22: Fascia - Straight | C22: 2 | D22: ea | E22: 9.5 | F22: =C22*E22 -> 19 | G22: This is for fixing a few rotted sections of soffit - s4s KD Pine 1x4x8
B23: Trim Nails | C23: 1 | D23: box | E23: 4 | F23: =C23*E23 -> 4 | G23: 1-1/2 in. Stainless Finishing Nails (50-Pack)
B24: Subtotal | F24: =SUM(F20:F23) -> 80
B26: INSULATION (south facing updated siding)
B27: Component / Description | C27: Quantity | D27: Unit | E27: Unit Cost | F27: Line Total | G27: Notes
B28: Batt Insulation R-15 | C28: 6 | D28: pack | E28: 75 | F28: =C28*E28 -> 450 | G28: R-15 Unfaced Fiberglass Insulation Batt 15 in. x 93 in.- 77 sq ft per bag
B29: Subtotal | F29: =SUM(F28:F28) -> 450
B31: GUTTERS
B32: Component / Description | C32: Quantity | D32: Unit | E32: Unit Cost | F32: Line Total | G32: Notes
B33: Gutter Corner | C33: 5 | D33: ea | E33: 16 | F33: =C33*E33 -> 80 | G33: 5"x10'
B34: Gutter Outlet | C34: 4 | D34: ea | E34: 11 | F34: =C34*E34 -> 44
B35: Gutter Connector | C35: 7 | D35: pack | E35: 8.8 | F35: =C35*E35 -> 61.6 | G35: Includes 2 per pack
B36: Gutter Downspout Elbow | C36: 4 | D36: ea | E36: 6 | F36: =C36*E36 -> 24 | G36: 3"x4"x10"
B37: Gutter Downspout | C37: 4 | D37: ea | E37: 33 | F37: =C37*E37 -> 132 | G37: 3"x4"x10"
B38: Straight Gutter Section | C38: 10 | D38: ea | E38: 18 | F38: =C38*E38 -> 180 | G38: 5"x10'
B39: Subtotal | F39: =SUM(F33:F38) -> 521.6
B41: WINDOWS + PATIO DOOR
B42: Component / Description | C42: Quantity | D42: Unit | E42: Unit Cost | F42: Line Total | G42: Notes
B43: Replacement Windows (double-hung) | C43: 5 | D43: ea | E43: 200 | F43: =C43*E43 -> 1000 | G43: South facing windows, 4x - 36x60, 1x - 36x36
B44: Sliding Patio Door (6ft) | C44: 1 | D44: ea | E44: 580 | F44: =C44*E44 -> 580 | G44: 72x80 ply gem slider
B45: Door Flashing
B46: Foam Sealant (cans) | C46: 2 | D46: can | E46: 10 | F46: =C46*E46 -> 20 | G46: Low-expansion, around window/door frames
...
